<?xml version='1.0' encoding='utf-8'?>
<mujoco model="adam_u">
  <compiler angle="radian" meshdir="meshes_stl_0.25/" />
  <asset>
    <mesh name="lifting_Columns" file="lifting_Columns.STL" />
    <mesh name="waistRoll_link" file="waistRoll_link.STL" />
    <mesh name="waistPitch_link" file="waistPitch_link.STL" />
    <mesh name="torso" file="torso.STL" />
    <mesh name="shoulderPitchLeft" file="shoulderPitchLeft.STL" />
    <mesh name="shoulderRollLeft" file="shoulderRollLeft.STL" />
    <mesh name="shoulderYawLeft" file="shoulderYawLeft.STL" />
    <mesh name="elbowLeft" file="elbowLeft.STL" />
    <mesh name="wristYawLeft" file="wristYawLeft.STL" />
    <mesh name="wristPitchLeft" file="wristPitchLeft.STL" />
    <mesh name="wristRollLeft" file="wristRollLeft.STL" />
    <mesh name="L_thumb_proximal_base" file="L_thumb_proximal_base.STL" />
    <mesh name="L_thumb_proximal" file="L_thumb_proximal.STL" />
    <mesh name="L_thumb_intermediate" file="L_thumb_intermediate.STL" />
    <mesh name="L_thumb_distal" file="L_thumb_distal.STL" />
    <mesh name="L_index_proximal" file="L_index_proximal.STL" />
    <mesh name="L_index_distal" file="L_index_distal.STL" />
    <mesh name="L_middle_proximal" file="L_middle_proximal.STL" />
    <mesh name="L_middle_distal" file="L_middle_distal.STL" />
    <mesh name="L_ring_proximal" file="L_ring_proximal.STL" />
    <mesh name="L_ring_distal" file="L_ring_distal.STL" />
    <mesh name="L_pinky_proximal" file="L_pinky_proximal.STL" />
    <mesh name="L_pinky_distal" file="L_pinky_distal.STL" />
    <mesh name="shoulderPitchRight" file="shoulderPitchRight.STL" />
    <mesh name="shoulderRollRight" file="shoulderRollRight.STL" />
    <mesh name="shoulderYawRight" file="shoulderYawRight.STL" />
    <mesh name="elbowRight" file="elbowRight.STL" />
    <mesh name="wristYawRight" file="wristYawRight.STL" />
    <mesh name="wristPitchRight" file="wristPitchRight.STL" />
    <mesh name="wristRollRight" file="wristRollRight.STL" />
    <mesh name="R_thumb_proximal_base" file="R_thumb_proximal_base.STL" />
    <mesh name="R_thumb_proximal" file="R_thumb_proximal.STL" />
    <mesh name="R_thumb_intermediate" file="R_thumb_intermediate.STL" />
    <mesh name="R_thumb_distal" file="R_thumb_distal.STL" />
    <mesh name="R_index_proximal" file="R_index_proximal.STL" />
    <mesh name="R_index_distal" file="R_index_distal.STL" />
    <mesh name="R_middle_proximal" file="R_middle_proximal.STL" />
    <mesh name="R_middle_distal" file="R_middle_distal.STL" />
    <mesh name="R_ring_proximal" file="R_ring_proximal.STL" />
    <mesh name="R_ring_distal" file="R_ring_distal.STL" />
    <mesh name="R_pinky_proximal" file="R_pinky_proximal.STL" />
    <mesh name="R_pinky_distal" file="R_pinky_distal.STL" />
    <mesh name="neckYaw_link" file="neckYaw_link.STL" />
    <mesh name="neckPitch_link" file="neckPitch_link.STL" />
  </asset>
  <worldbody>
    <body name="lifting_Columns" pos="0 0 1.05">
      <inertial pos="9.03635e-05 -3.16723e-05 -0.722725" quat="0.499642 0.499654 -0.50034 0.500364" mass="16.1205" diaginertia="0.720003 0.582931 0.351926" />
      <joint name="floating_base" type="free" limited="false" actuatorfrclimited="false" />
      <geom type="mesh" contype="0" conaffinity="0" group="1" density="0" rgba="1 1 1 1" mesh="lifting_Columns" />
      <geom type="box" rgba="1 0 0 0." size="1 1 0.05" pos="0 0 -.985"/>
      <body name="waistRoll_link" pos="0 0 0.0767">
        <inertial pos="0.00093826 0.00093832 0.0399999" quat="0.383833 0.0123801 -0.00511148 0.923305" mass="2.36268" diaginertia="0.00543471 0.00542871 0.00184736" />
        <joint name="waistRoll" pos="0 0 0" axis="1 0 0" range="-0.279 0.279" actuatorfrcrange="-110 110" damping="0"/>
        <geom type="mesh" contype="0" conaffinity="0" group="1" density="0" rgba="1 1 1 1" mesh="waistRoll_link" />

        <body name="waistPitch_link" pos="0 0 0.08">
          <inertial pos="-8.401e-05 0.00189362 0.0254832" quat="0.516813 0.52977 -0.475496 0.475554" mass="0.563538" diaginertia="0.00155964 0.00151442 0.000672501" />
          <joint name="waistPitch" pos="0 0 0" axis="0 1 0" range="-0.663 1.361" actuatorfrcrange="-110 110" damping="0"/>
          <geom type="mesh" contype="0" conaffinity="0" group="1" density="0" rgba="0.752941 0.752941 0.752941 1" mesh="waistPitch_link" />

          <body name="torso" pos="0 0.0005 0.053">
            <inertial pos="-0.00183601 0.00056583 0.166624" quat="0.999453 -0.000219402 0.032831 -0.00390757" mass="12.7334" diaginertia="0.13029 0.0859384 0.0736824" />
            <joint name="waistYaw" pos="0 0 0" axis="0 0 1" range="-0.829 0.829" actuatorfrcrange="-110 110" damping="0"/>
            <geom type="mesh" contype="0" conaffinity="0" group="1" density="0" rgba="0.752941 0.752941 0.752941 1" mesh="torso" />

            <body name="shoulderPitchLeft" pos="0 0.165094 0.25923" quat="0.984808 0.173648 0 0">
              <inertial pos="0.00542694 0.0268987 0.00010792" quat="0.0525836 0.7027 -0.0564441 0.707292" mass="0.216148" diaginertia="0.000380649 0.000322752 0.000187229" />
              <joint name="shoulderPitch_Left" pos="0 0 0" axis="0 1 0" range="-3.613 2.042" actuatorfrcrange="-65 65" damping="3"/>
              <geom type="mesh" contype="0" conaffinity="0" group="1" density="0" rgba="1 1 1 1" mesh="shoulderPitchLeft" />
              <geom type="mesh" rgba="1 1 1 1" mesh="shoulderPitchLeft" />
              <body name="shoulderRollLeft" pos="0.0362 0.0435 0" quat="0.984808 -0.173648 0 0">
                <inertial pos="-0.0343733 0.00962154 -0.0154456" quat="0.915483 -0.248083 -0.0900009 -0.303719" mass="1.07882" diaginertia="0.0016821 0.0016513 0.000668275" />
                <joint name="shoulderRoll_Left" pos="0 0 0" axis="1 0 0" range="-0.628 2.793" actuatorfrcrange="-65 65" damping="3"/>
                <geom type="mesh" contype="0" conaffinity="0" group="1" density="0" rgba="0.752941 0.752941 0.752941 1" mesh="shoulderRollLeft" />
                <!-- <geom type="mesh" rgba="0.752941 0.752941 0.752941 1" mesh="shoulderRollLeft" /> -->
                <body name="shoulderYawLeft" pos="-0.0362 0.034 -0.0797">
                  <inertial pos="-0.00051421 -0.00044442 -0.0619328" quat="0.999905 0.00947141 -0.00878878 0.00478573" mass="0.90142" diaginertia="0.00328642 0.00317319 0.000574119" />
                  <joint name="shoulderYaw_Left" pos="0 0 0" axis="0 0 1" range="-2.583 2.583" actuatorfrcrange="-65 65" damping="5"/>
                  <geom type="mesh" contype="0" conaffinity="0" group="1" density="0" rgba="1 1 1 1" mesh="shoulderYawLeft" />
                  <geom type="mesh" rgba="1 1 1 1" mesh="shoulderYawLeft" />
                  <body name="elbowLeft" pos="0 -0.0285 -0.18295">
                    <inertial pos="-0.0140727 0.0292971 -0.0253473" quat="0.882767 -0.0885577 -0.220164 0.405471" mass="0.917707" diaginertia="0.0011212 0.00108213 0.000458232" />
                    <joint name="elbow_Left" pos="0 0 0" axis="0 1 0" range="-2.496 0.209" actuatorfrcrange="-30 30" damping="3"/>
                    <geom type="mesh" contype="0" conaffinity="0" group="1" density="0" rgba="0.752941 0.752941 0.752941 1" mesh="elbowLeft" />

                    <body name="wristYawLeft" pos="-0.025 0.0285 -0.0729">
                      <inertial pos="-0.00174399 0.0001059 -0.0921606" quat="0.999598 -0.00413874 -0.00815289 -0.0268553" mass="0.955879" diaginertia="0.00254024 0.0024845 0.00052605" />
                      <joint name="wristYaw_Left" pos="0 0 0" axis="0 0 1" range="-2.67 2.67" actuatorfrcrange="-6.4 6.4" damping="3"/>
                      <geom type="mesh" contype="0" conaffinity="0" group="1" density="0" rgba="0.752941 0.752941 0.752941 1" mesh="wristYawLeft" />
                      <geom type="mesh" rgba="0.752941 0.752941 0.752941 1" mesh="wristYawLeft" />
                      <body name="wristPitchLeft" pos="0 0 -0.2017">
                        <inertial pos="-0.00017582 0.00166098 -2.773e-05" quat="0.498275 0.501712 -0.500227 0.499779" mass="0.119635" diaginertia="3.97702e-05 3.35901e-05 2.68997e-05" />
                        <joint name="wristPitch_Left" pos="0 0 0" axis="0 1 0" range="-0.96 0.96" actuatorfrcrange="-6.4 6.4" damping="3"/>
                        <geom type="mesh" contype="0" conaffinity="0" group="1" density="0" rgba="1 1 1 1" mesh="wristPitchLeft" />

                        <body name="wristRollLeft">
                          <inertial pos="-0.00027229 0.00864497 -0.0662702" quat="0.743139 -0.0248702 0.0370789 0.667646" mass="0.357497" diaginertia="0.000432717 0.000318933 0.0001829" />
                          <joint name="wristRoll_Left" pos="0 0 0" axis="1 0 0" range="-0.96 0.96" actuatorfrcrange="-6.4 6.4" damping="3"/>
                          <geom type="mesh" contype="0" conaffinity="0" group="1" density="0" rgba="0.752941 0.752941 0.752941 1" mesh="wristRollLeft" />
                          <!-- <geom type="mesh" rgba="0.752941 0.752941 0.752941 1" mesh="wristRollLeft" /> -->
                          <body name="L_thumb_proximal_base" pos="0.0245 -0.01 -0.047">
                            <inertial pos="0.00431634 0.00026726 -0.00141885" quat="0.402129 0.420407 0.428718 0.691196" mass="0.0089319" diaginertia="5.80786e-07 4.69278e-07 2.69935e-07" />
                            <!-- <joint name="L_thumb_MCP_joint1" pos="0 0 0" axis="0 0 -1" range="0 1.1" actuatorfrcrange="-1 1" damping="100"/> -->
                            <geom type="mesh" contype="0" conaffinity="0" group="1" density="0" rgba="0.752941 0.752941 0.752941 1" mesh="L_thumb_proximal_base" />
 
                            <body name="L_thumb_proximal" pos="0.011954 -0.00104968 0" quat="0.999041 0 0 -0.0437786">
                              <inertial pos="0.0236969 0 -0.0146724" quat="0.655148 0.266048 0.266048 0.655148" mass="0.0615843" diaginertia="2.013e-05 1.73022e-05 5.79777e-06" />
                              <!-- <joint name="L_thumb_MCP_joint2" pos="0 0 0" axis="0 1 0" range="0 0.5" actuatorfrcrange="-1 1" damping="100"/> -->
                              <geom type="mesh" contype="0" conaffinity="0" group="1" density="0" rgba="0.752941 0.752941 0.752941 1" mesh="L_thumb_proximal" />

                              <body name="L_thumb_intermediate" pos="0.0442886 0 -0.0376633">
                                <inertial pos="0.00973134 0 -0.00266466" quat="0.681637 0.188072 0.188072 0.681637" mass="0.0153834" diaginertia="1.72e-06 1.65294e-06 7.67055e-07" />
                                <!-- <joint name="L_thumb_PIP_joint" pos="0 0 0" axis="0 1 0" range="0 1" actuatorfrcrange="-1 1" damping="100"/> -->
                                <geom type="mesh" contype="0" conaffinity="0" group="1" density="0" rgba="0.752941 0.752941 0.752941 1" mesh="L_thumb_intermediate" />

                                <body name="L_thumb_distal" pos="0.0164679 0 -0.0154615">
                                  <inertial pos="0.00714221 -1.54e-06 -0.00689404" quat="0.967006 0 0.254755 0" mass="0.0104374" diaginertia="8.73238e-07 8.6e-07 4.06762e-07" />
                                  <!-- <joint name="L_thumb_DIP_joint" pos="0 0 0" axis="0 1 0" range="0 1.2" actuatorfrcrange="-1 1" damping="100"/> -->
                                  <geom type="mesh" contype="0" conaffinity="0" group="1" density="0" rgba="0.752941 0.752941 0.752941 1" mesh="L_thumb_distal" />

                                </body>
                              </body>
                            </body>
                          </body>
                          <body name="L_index_proximal" pos="0.026942 0.0095 -0.114975" quat="0.999657 0 -0.0261769 0">
                            <inertial pos="0 0.00199817 -0.0131171" quat="0.707089 0.00501356 -0.00501356 0.707089" mass="0.0145411" diaginertia="1.95028e-06 1.95e-06 5.39716e-07" />
                            <!-- <joint name="L_index_MCP_joint" pos="0 0 0" axis="-1 0 0" range="0 1.7" actuatorfrcrange="-1 1" damping="100"/> -->
                            <geom type="mesh" contype="0" conaffinity="0" group="1" density="0" rgba="0.752941 0.752941 0.752941 1" mesh="L_index_proximal" />
                            <geom type="mesh" rgba="0.752941 0.752941 0.752941 1" mesh="L_index_proximal" />
                            <body name="L_index_distal" pos="0 -0.00111269 -0.0319806">
                              <inertial pos="0 0.00168954 -0.0153694" quat="0.996466 0.0839918 0 0" mass="0.00905901" diaginertia="1.73e-06 1.72245e-06 2.07554e-07" />
                              <!-- <joint name="L_index_DIP_joint" pos="0 0 0" axis="-1 0 0" range="0 1.6" actuatorfrcrange="-1 1" damping="100"/> -->
                              <geom type="mesh" contype="0" conaffinity="0" group="1" density="0" rgba="0.752941 0.752941 0.752941 1" mesh="L_index_distal" />
                              <geom type="mesh" rgba="0.752941 0.752941 0.752941 1" mesh="L_index_distal" />
                            </body>
                          </body>
                          <body name="L_middle_proximal" pos="0.008 0.0145 -0.128">
                            <inertial pos="0 0.00115546 -0.0133419" quat="0.999362 0.0357184 0 0" mass="0.013131" diaginertia="1.94e-06 1.93716e-06 5.32843e-07" />
                            <!-- <joint name="L_middle_MCP_joint" pos="0 0 0" axis="-1 0 0" range="0 1.7" actuatorfrcrange="-1 1" damping="100"/> -->
                            <geom type="mesh" contype="0" conaffinity="0" group="1" density="0" rgba="0.752941 0.752941 0.752941 1" mesh="L_middle_proximal" />
                            <geom type="mesh" rgba="0.752941 0.752941 0.752941 1" mesh="L_middle_proximal" />
                            <body name="L_middle_distal" pos="0 -0.00293735 -0.0318649">
                              <inertial pos="0 -3.933e-05 -0.0154619" quat="0.990386 0.138332 0 0" mass="0.00905901" diaginertia="1.73e-06 1.72396e-06 2.06037e-07" />
                              <!-- <joint name="L_middle_DIP_joint" pos="0 0 0" axis="-1 0 0" range="0 1.6" actuatorfrcrange="-1 1" damping="100"/> -->
                              <geom type="mesh" contype="0" conaffinity="0" group="1" density="0" rgba="0.752941 0.752941 0.752941 1" mesh="L_middle_distal" />
                              <geom type="mesh" rgba="0.752941 0.752941 0.752941 1" mesh="L_middle_distal" />
                            </body>
                          </body>
                          <body name="L_ring_proximal" pos="-0.010942 0.0095 -0.119975" quat="0.999657 0 0.0261769 0">
                            <inertial pos="-3.95e-06 0.00199338 -0.0131311" quat="0.707089 0.00501356 -0.00501356 0.707089" mass="0.0145411" diaginertia="1.95028e-06 1.95e-06 5.39716e-07" />
                            <!-- <joint name="L_ring_MCP_joint" pos="0 0 0" axis="-1 0 0" range="0 1.7" actuatorfrcrange="-1 1" damping="100"/> -->
                            <geom type="mesh" contype="0" conaffinity="0" group="1" density="0" rgba="0.752941 0.752941 0.752941 1" mesh="L_ring_proximal" />
                            <geom type="mesh" rgba="0.752941 0.752941 0.752941 1" mesh="L_ring_proximal" />
                            <body name="L_ring_distal" pos="0 -0.00111269 -0.0319806">
                              <inertial pos="0 0.00168954 -0.0153694" quat="0.996466 0.0839918 0 0" mass="0.00905901" diaginertia="1.73e-06 1.72245e-06 2.07554e-07" />
                              <!-- <joint name="L_ring_DIP_joint" pos="0 0 0" axis="-1 0 0" range="0 1.6" actuatorfrcrange="-1 1" damping="100"/> -->
                              <geom type="mesh" contype="0" conaffinity="0" group="1" density="0" rgba="0.752941 0.752941 0.752941 1" mesh="L_ring_distal" />
                              <geom type="mesh" rgba="0.752941 0.752941 0.752941 1" mesh="L_ring_distal" />
                            </body>
                          </body>
                          <body name="L_pinky_proximal" pos="-0.0301936 0.0045 -0.112866" quat="0.998135 0 0.0610485 0">
                            <inertial pos="0 0.00191043 -0.0132257" quat="0.707089 0.00501356 -0.00501356 0.707089" mass="0.013131" diaginertia="1.94028e-06 1.94e-06 5.29716e-07" />
                            <!-- <joint name="L_pinky_MCP_joint" pos="0 0 0" axis="-1 0 0" range="0 1.7" actuatorfrcrange="-1 1" damping="100"/> -->
                            <geom type="mesh" contype="0" conaffinity="0" group="1" density="0" rgba="0.752941 0.752941 0.752941 1" mesh="L_pinky_proximal" />
                            <geom type="mesh" rgba="0.752941 0.752941 0.752941 1" mesh="L_pinky_proximal" />
                            <body name="L_pinky_distal" pos="0 -0.00111269 -0.0319806">
                              <inertial pos="1.99e-06 0.00260409 -0.0109991" quat="0.997444 0.0714519 0 0" mass="0.00693901" diaginertia="8.6e-07 8.54401e-07 1.45599e-07" />
                              <!-- <joint name="L_pinky_DIP_joint" pos="0 0 0" axis="-1 0 0" range="0 1.6" actuatorfrcrange="-1 1" damping="100"/> -->
                              <geom type="mesh" contype="0" conaffinity="0" group="1" density="0" rgba="0.752941 0.752941 0.752941 1" mesh="L_pinky_distal" />
                              <geom type="mesh" rgba="0.752941 0.752941 0.752941 1" mesh="L_pinky_distal" />
                            </body>
                          </body>
                        </body>
                      </body>
                    </body>
                  </body>
                </body>
              </body>
            </body>
            <body name="shoulderPitchRight" pos="0 -0.165094 0.25923" quat="0.984808 -0.173648 0 0">
              <inertial pos="0.00536737 -0.0269397 0.00010693" quat="-0.0515608 0.702788 0.055363 0.707365" mass="0.216487" diaginertia="0.000381339 0.000323121 0.00018756" />
              <joint name="shoulderPitch_Right" pos="0 0 0" axis="0 1 0" range="-3.613 2.042" actuatorfrcrange="-65 65" damping="3"/>
              <geom type="mesh" contype="0" conaffinity="0" group="1" density="0" rgba="1 1 1 1" mesh="shoulderPitchRight" />
              <geom type="mesh" rgba="1 1 1 1" mesh="shoulderPitchRight" />
              <body name="shoulderRollRight" pos="0.0362 -0.0435 0" quat="0.984808 0.173648 0 0">
                <inertial pos="-0.0342995 -0.00987424 -0.0157184" quat="0.928314 0.252353 -0.0795949 0.26118" mass="1.08875" diaginertia="0.00170392 0.001678 0.000675842" />
                <joint name="shoulderRoll_Right" pos="0 0 0" axis="1 0 0" range="-2.793 0.628" actuatorfrcrange="-65 65" damping="3"/>
                <geom type="mesh" contype="0" conaffinity="0" group="1" density="0" rgba="0.752941 0.752941 0.752941 1" mesh="shoulderRollRight" />
                <!-- <geom type="mesh" rgba="0.752941 0.752941 0.752941 1" mesh="shoulderRollRight" /> -->
                <body name="shoulderYawRight" pos="-0.0362 -0.034 -0.0797">
                  <inertial pos="-0.00051403 0.00046316 -0.0619299" quat="0.999913 -0.00947141 -0.00876739 -0.00265779" mass="0.901393" diaginertia="0.0032861 0.00317291 0.000574074" />
                  <joint name="shoulderYaw_Right" pos="0 0 0" axis="0 0 1" range="-2.583 2.583" actuatorfrcrange="-65 65" damping="5"/>
                  <geom type="mesh" contype="0" conaffinity="0" group="1" density="0" rgba="1 1 1 1" mesh="shoulderYawRight" />
                  <geom type="mesh" rgba="1 1 1 1" mesh="shoulderYawRight" />
                  <body name="elbowRight" pos="0 0.0285 -0.18295">
                    <inertial pos="-0.0140891 -0.0292958 -0.0253475" quat="0.405211 -0.22003 -0.0882783 0.882948" mass="0.917707" diaginertia="0.00112054 0.00108207 0.000458081" />
                    <joint name="elbow_Right" pos="0 0 0" axis="0 1 0" range="-2.496 0.209" actuatorfrcrange="-30 30" damping="3"/>
                    <geom type="mesh" contype="0" conaffinity="0" group="1" density="0" rgba="0.752941 0.752941 0.752941 1" mesh="elbowRight" />

                    <body name="wristYawRight" pos="-0.025 -0.0285 -0.0729">
                      <inertial pos="-0.00173086 -0.00013146 -0.0921689" quat="0.999586 0.00431062 -0.00814756 0.0272448" mass="0.955878" diaginertia="0.00254074 0.00248448 0.000525569" />
                      <joint name="wristYaw_Right" pos="0 0 0" axis="0 0 1" range="-2.67 2.67" actuatorfrcrange="-6.4 6.4" damping="3"/>
                      <geom type="mesh" contype="0" conaffinity="0" group="1" density="0" rgba="0.752941 0.752941 0.752941 1" mesh="wristYawRight" />
                      <geom type="mesh" rgba="0.752941 0.752941 0.752941 1" mesh="wristYawRight" />
                      <body name="wristPitchRight" pos="0 0 -0.2017">
                        <inertial pos="-0.0001758 0.00166098 -2.773e-05" quat="0.498275 0.501712 -0.500227 0.499779" mass="0.119635" diaginertia="3.97702e-05 3.35901e-05 2.68997e-05" />
                        <joint name="wristPitch_Right" pos="0 0 0" axis="0 1 0" range="-0.96 0.96" actuatorfrcrange="-6.4 6.4" damping="3"/>
                        <geom type="mesh" contype="0" conaffinity="0" group="1" density="0" rgba="1 1 1 1" mesh="wristPitchRight" />

                        <body name="wristRollRight">
                          <inertial pos="-0.00030616 -0.00861825 -0.0663443" quat="0.666961 0.0378803 -0.0231418 0.743769" mass="0.358155" diaginertia="0.000433212 0.000319556 0.000183031" />
                          <joint name="wristRoll_Right" pos="0 0 0" axis="1 0 0" range="-0.96 0.96" actuatorfrcrange="-6.4 6.4" damping="3"/>
                          <geom type="mesh" contype="0" conaffinity="0" group="1" density="0" rgba="0.752941 0.752941 0.752941 1" mesh="wristRollRight" />
                          <!-- <geom type="mesh" rgba="0.752941 0.752941 0.752941 1" mesh="wristRollRight" /> -->
                          <body name="R_thumb_proximal_base" pos="0.0245 0.01 -0.047">
                            <inertial pos="0.00431634 -0.00026726 -0.00141884" quat="0.691196 0.428718 0.420407 0.402129" mass="0.0089319" diaginertia="5.80786e-07 4.69278e-07 2.69935e-07" />
                            <!-- <joint name="R_thumb_MCP_joint1" pos="0 0 0" axis="0 0 1" range="0 1.1" actuatorfrcrange="-1 1" damping="100"/> -->
                            <geom type="mesh" contype="0" conaffinity="0" group="1" density="0" rgba="0.752941 0.752941 0.752941 1" mesh="R_thumb_proximal_base" />

                            <body name="R_thumb_proximal" pos="0.011954 0.00104968 0" quat="0.999041 0 0 0.0437786">
                              <inertial pos="0.0236968 0 -0.0146723" quat="0.655148 0.266048 0.266048 0.655148" mass="0.0615843" diaginertia="2.013e-05 1.73022e-05 5.79777e-06" />
                              <!-- <joint name="R_thumb_MCP_joint2" pos="0 0 0" axis="0 1 0" range="0 0.5" actuatorfrcrange="-1 1" damping="100"/> -->
                              <geom type="mesh" contype="0" conaffinity="0" group="1" density="0" rgba="0.752941 0.752941 0.752941 1" mesh="R_thumb_proximal" />

                              <body name="R_thumb_intermediate" pos="0.0442886 0 -0.0376633">
                                <inertial pos="0.00973134 0 -0.00266467" quat="0.681637 0.188072 0.188072 0.681637" mass="0.0153834" diaginertia="1.72e-06 1.65294e-06 7.67055e-07" />
                                <!-- <joint name="R_thumb_PIP_joint" pos="0 0 0" axis="0 1 0" range="0 1" actuatorfrcrange="-1 1" damping="100"/> -->
                                <geom type="mesh" contype="0" conaffinity="0" group="1" density="0" rgba="0.752941 0.752941 0.752941 1" mesh="R_thumb_intermediate" />

                                <body name="R_thumb_distal" pos="0.0164679 0 -0.0154615">
                                  <inertial pos="0.00714151 1.39e-06 -0.00689413" quat="0.967006 0 0.254755 0" mass="0.0104374" diaginertia="8.73238e-07 8.6e-07 4.06762e-07" />
                                  <!-- <joint name="R_thumb_DIP_joint" pos="0 0 0" axis="0 1 0" range="0 1.2" actuatorfrcrange="-1 1" damping="100"/> -->
                                  <geom type="mesh" contype="0" conaffinity="0" group="1" density="0" rgba="0.752941 0.752941 0.752941 1" mesh="R_thumb_distal" />

                                </body>
                              </body>
                            </body>
                          </body>
                          <body name="R_index_proximal" pos="0.026942 -0.0095 -0.114975" quat="0.999657 0 -0.0261769 0">
                            <inertial pos="0 -0.0019982 -0.0131171" quat="0.707089 -0.00501356 0.00501356 0.707089" mass="0.0145412" diaginertia="1.95028e-06 1.95e-06 5.39716e-07" />
                            <!-- <joint name="R_index_MCP_joint" pos="0 0 0" axis="1 0 0" range="0 1.7" actuatorfrcrange="-1 1" damping="100"/> -->
                            <geom type="mesh" contype="0" conaffinity="0" group="1" density="0" rgba="0.752941 0.752941 0.752941 1" mesh="R_index_proximal" />
                            <geom type="mesh" rgba="0.752941 0.752941 0.752941 1" mesh="R_index_proximal" />
                            <body name="R_index_distal" pos="0 0.00111269 -0.0319806">
                              <inertial pos="0 -0.00168936 -0.0153697" quat="0.996466 -0.0839918 0 0" mass="0.00905901" diaginertia="1.73e-06 1.72245e-06 2.07554e-07" />
                              <joint name="R_index_DIP_joint" pos="0 0 0" axis="1 0 0" range="0 1.6" actuatorfrcrange="-1 1" damping="100"/>
                              <geom type="mesh" contype="0" conaffinity="0" group="1" density="0" rgba="0.752941 0.752941 0.752941 1" mesh="R_index_distal" />
                              <geom type="mesh" rgba="0.752941 0.752941 0.752941 1" mesh="R_index_distal" />
                            </body>
                          </body>
                          <body name="R_middle_proximal" pos="0.008 -0.0145 -0.128">
                            <inertial pos="0 -0.00115549 -0.0133419" quat="0.999362 -0.0357184 0 0" mass="0.0131311" diaginertia="1.94e-06 1.93716e-06 5.32843e-07" />
                            <!-- <joint name="R_middle_MCP_joint" pos="0 0 0" axis="1 0 0" range="0 1.7" actuatorfrcrange="-1 1" damping="100"/> -->
                            <geom type="mesh" contype="0" conaffinity="0" group="1" density="0" rgba="0.752941 0.752941 0.752941 1" mesh="R_middle_proximal" />
                            <geom type="mesh" rgba="0.752941 0.752941 0.752941 1" mesh="R_middle_proximal" />
                            <body name="R_middle_distal" pos="0 0.00293735 -0.0318649">
                              <inertial pos="0 3.955e-05 -0.0154622" quat="0.990386 -0.138332 0 0" mass="0.00905901" diaginertia="1.73e-06 1.72396e-06 2.06037e-07" />
                              <!-- <joint name="R_middle_DIP_joint" pos="0 0 0" axis="1 0 0" range="0 1.6" actuatorfrcrange="-1 1" damping="100"/> -->
                              <geom type="mesh" contype="0" conaffinity="0" group="1" density="0" rgba="0.752941 0.752941 0.752941 1" mesh="R_middle_distal" />
                              <geom type="mesh" rgba="0.752941 0.752941 0.752941 1" mesh="R_middle_distal" />
                            </body>
                          </body>
                          <body name="R_ring_proximal" pos="-0.010942 -0.0095 -0.119975" quat="0.999657 0 0.0261769 0">
                            <inertial pos="0 -0.0019982 -0.0131171" quat="0.707089 -0.00501356 0.00501356 0.707089" mass="0.0145412" diaginertia="1.95028e-06 1.95e-06 5.39716e-07" />
                            <!-- <joint name="R_ring_MCP_joint" pos="0 0 0" axis="1 0 0" range="0 1.7" actuatorfrcrange="-1 1" damping="100"/> -->
                            <geom type="mesh" contype="0" conaffinity="0" group="1" density="0" rgba="0.752941 0.752941 0.752941 1" mesh="R_ring_proximal" />
                            <geom type="mesh" rgba="0.752941 0.752941 0.752941 1" mesh="R_ring_proximal" />
                            <body name="R_ring_distal" pos="0 0.00111269 -0.0319806">
                              <inertial pos="0 -0.00168936 -0.0153697" quat="0.996466 -0.0839918 0 0" mass="0.00905901" diaginertia="1.73e-06 1.72245e-06 2.07554e-07" />
                              <!-- <joint name="R_ring_DIP_joint" pos="0 0 0" axis="1 0 0" range="0 1.6" actuatorfrcrange="-1 1" damping="100"/> -->
                              <geom type="mesh" contype="0" conaffinity="0" group="1" density="0" rgba="0.752941 0.752941 0.752941 1" mesh="R_ring_distal" />
                              <geom type="mesh" rgba="0.752941 0.752941 0.752941 1" mesh="R_ring_distal" />
                            </body>
                          </body>
                          <body name="R_pinky_proximal" pos="-0.0301936 -0.0045 -0.112866" quat="0.998135 0 0.0610485 0">
                            <inertial pos="0 -0.00191046 -0.0132258" quat="0.707089 -0.00501356 0.00501356 0.707089" mass="0.0131311" diaginertia="1.94028e-06 1.94e-06 5.29716e-07" />
                            <!-- <joint name="R_pinky_MCP_joint" pos="0 0 0" axis="1 0 0" range="0 1.7" actuatorfrcrange="-1 1" damping="100"/> -->
                            <geom type="mesh" contype="0" conaffinity="0" group="1" density="0" rgba="0.752941 0.752941 0.752941 1" mesh="R_pinky_proximal" />
                            <geom type="mesh" rgba="0.752941 0.752941 0.752941 1" mesh="R_pinky_proximal" />
                            <body name="R_pinky_distal" pos="0 0.00111269 -0.0319806">
                              <inertial pos="2.01e-06 -0.00260417 -0.0109989" quat="0.997444 -0.0714519 0 0" mass="0.00693901" diaginertia="8.6e-07 8.54401e-07 1.45599e-07" />
                              <!-- <joint name="R_pinky_DIP_joint" pos="0 0 0" axis="1 0 0" range="0 1.6" actuatorfrcrange="-1 1" damping="10"/> -->
                              <geom type="mesh" contype="0" conaffinity="0" group="1" density="0" rgba="0.752941 0.752941 0.752941 1" mesh="R_pinky_distal" />
                              <geom type="mesh" rgba="0.752941 0.752941 0.752941 1" mesh="R_pinky_distal" />
                            </body>
                          </body>
                        </body>
                      </body>
                    </body>
                  </body>
                </body>
              </body>
            </body>
            <body name="neckYaw_link" pos="-0.013 0 0.29855">
              <inertial pos="0.0228442 -0.00120876 0.0992634" quat="0.495063 -0.105336 -0.0540824 0.860751" mass="0.399168" diaginertia="0.00132695 0.00131013 0.000128728" />
              <joint name="neckYaw" pos="0 0 0" axis="0 0 1" range="-1.571 1.571" actuatorfrcrange="-6.4 6.4" damping="0"/>
              <geom type="mesh" contype="0" conaffinity="0" group="1" density="0" rgba="0.752941 0.752941 0.752941 1" mesh="neckYaw_link" />
              <geom type="mesh" rgba="0.752941 0.752941 0.752941 1" mesh="neckYaw_link" />
              <body name="neckPitch_link" pos="0.0316 0.01995 0.14595">
                <inertial pos="0.0174597 -0.0210407 0.0470534" quat="0.0247474 0.519975 0.0323442 0.85321" mass="0.956204" diaginertia="0.00368918 0.00348892 0.00231144" />
                <joint name="neckPitch" pos="0 0 0" axis="0 1 0" range="-0.873 0.873" actuatorfrcrange="-6.4 6.4" damping="0"/>
                <geom type="mesh" contype="0" conaffinity="0" group="1" density="0" rgba="0.752941 0.752941 0.752941 1" mesh="neckPitch_link" />
                <geom type="mesh" rgba="0.752941 0.752941 0.752941 1" mesh="neckPitch_link" />
              </body>
            </body>
          </body>
        </body>
      </body>
    </body>
  </worldbody>
  <actuator>
    <motor joint="waistRoll" name="waistRoll" ctrlrange="-110.0 110.0" />
    <motor joint="waistPitch" name="waistPitch" ctrlrange="-110.0 110.0" />
    <motor joint="waistYaw" name="waistYaw" ctrlrange="-110.0 110.0" />
    <motor joint="neckYaw" name="neckYaw" ctrlrange="-6.4 6.4" />
    <motor joint="neckPitch" name="neckPitch" ctrlrange="-6.4 6.4" />
    <motor joint="shoulderPitch_Left" name="shoulderPitch_Left" ctrlrange="-65.0 65.0" />
    <motor joint="shoulderRoll_Left" name="shoulderRoll_Left" ctrlrange="-65.0 65.0" />
    <motor joint="shoulderYaw_Left" name="shoulderYaw_Left" ctrlrange="-65.0 65.0" />
    <motor joint="elbow_Left" name="elbow_Left" ctrlrange="-30.0 30.0" />
    <motor joint="wristYaw_Left" name="wristYaw_Left" ctrlrange="-6.4 6.4" />
    <motor joint="wristPitch_Left" name="wristPitch_Left" ctrlrange="-6.4 6.4" />
    <motor joint="wristRoll_Left" name="wristRoll_Left" ctrlrange="-6.4 6.4" />
    <motor joint="shoulderPitch_Right" name="shoulderPitch_Right" ctrlrange="-65.0 65.0" />
    <motor joint="shoulderRoll_Right" name="shoulderRoll_Right" ctrlrange="-65.0 65.0" />
    <motor joint="shoulderYaw_Right" name="shoulderYaw_Right" ctrlrange="-65.0 65.0" />
    <motor joint="elbow_Right" name="elbow_Right" ctrlrange="-30.0 30.0" />
    <motor joint="wristYaw_Right" name="wristYaw_Right" ctrlrange="-6.4 6.4" />
    <motor joint="wristPitch_Right" name="wristPitch_Right" ctrlrange="-6.4 6.4" />
    <motor joint="wristRoll_Right" name="wristRoll_Right" ctrlrange="-6.4 6.4" />
    <!-- <position joint="waistRoll" name="waistRoll" ctrlrange="-2.0 2.0" kp="60" />
    <position joint="waistPitch" name="waistPitch" ctrlrange="-2.0 2.0" kp="60" />
    <position joint="waistYaw" name="waistYaw" ctrlrange="-2.0 2.0" kp="60" />
    <position joint="neckYaw" name="neckYaw" ctrlrange="-2.0 2.0" kp="9" />
    <position joint="neckPitch" name="neckPitch" ctrlrange="-2.0 2.0" kp="9" />

    <position joint="shoulderPitch_Left" name="shoulderPitch_Left" ctrlrange="-2.0 2.0" kp="18" />
    <position joint="shoulderRoll_Left" name="shoulderRoll_Left" ctrlrange="-2.0 2.0" kp="9" />
    <position joint="shoulderYaw_Left" name="shoulderYaw_Left" ctrlrange="-2.0 2.0" kp="9" />
    <position joint="elbow_Left" name="elbow_Left" ctrlrange="-2.0 2.0" kp="9" />
    <position joint="wristYaw_Left" name="wristYaw_Left" ctrlrange="-2.0 2.0" kp="9" />
    <position joint="wristPitch_Left" name="wristPitch_Left" ctrlrange="-2.0 2.0" kp="9" />
    <position joint="wristRoll_Left" name="wristRoll_Left" ctrlrange="-2.0 2.0" kp="9" />

    <position joint="shoulderPitch_Right" name="shoulderPitch_Right" ctrlrange="-2.0 2.0" kp="18" />
    <position joint="shoulderRoll_Right" name="shoulderRoll_Right" ctrlrange="-2.0 2.0" kp="9" />
    <position joint="shoulderYaw_Right" name="shoulderYaw_Right" ctrlrange="-2.0 2.0" kp="9" />
    <position joint="elbow_Right" name="elbow_Right" ctrlrange="-2.0 2.0" kp="9" />
    <position joint="wristYaw_Right" name="wristYaw_Right" ctrlrange="-2.0 2.0" kp="9" />
    <position joint="wristPitch_Right" name="wristPitch_Right" ctrlrange="-2.0 2.0" kp="9" />
    <position joint="wristRoll_Right" name="wristRoll_Right" ctrlrange="-2.0 2.0" kp="9" /> -->
  </actuator>
  <sensor>
    <jointpos name="pos_waistRoll" joint="waistRoll" />
    <jointpos name="pos_waistPitch" joint="waistPitch" />
    <jointpos name="pos_waistYaw" joint="waistYaw" />
    <jointpos name="pos_neckYaw" joint="neckYaw" />
    <jointpos name="pos_neckPitch" joint="neckPitch" />
    <jointpos name="pos_shoulderPitch_Left" joint="shoulderPitch_Left" />
    <jointpos name="pos_shoulderRoll_Left" joint="shoulderRoll_Left" />
    <jointpos name="pos_shoulderYaw_Left" joint="shoulderYaw_Left" />
    <jointpos name="pos_elbow_Left" joint="elbow_Left" />
    <jointpos name="pos_wristYaw_Left" joint="wristYaw_Left" />
    <jointpos name="pos_wristPitch_Left" joint="wristPitch_Left" />
    <jointpos name="pos_wristRoll_Left" joint="wristRoll_Left" />
    <jointpos name="pos_shoulderPitch_Right" joint="shoulderPitch_Right" />
    <jointpos name="pos_shoulderRoll_Right" joint="shoulderRoll_Right" />
    <jointpos name="pos_shoulderYaw_Right" joint="shoulderYaw_Right" />
    <jointpos name="pos_elbow_Right" joint="elbow_Right" />
    <jointpos name="pos_wristYaw_Right" joint="wristYaw_Right" />
    <jointpos name="pos_wristPitch_Right" joint="wristPitch_Right" />
    <jointpos name="pos_wristRoll_Right" joint="wristRoll_Right" />
    <jointvel name="vel_waistRoll" joint="waistRoll" />
    <jointvel name="vel_waistPitch" joint="waistPitch" />
    <jointvel name="vel_waistYaw" joint="waistYaw" />
    <jointvel name="vel_neckYaw" joint="neckYaw" />
    <jointvel name="vel_neckPitch" joint="neckPitch" />
    <jointvel name="vel_shoulderPitch_Left" joint="shoulderPitch_Left" />
    <jointvel name="vel_shoulderRoll_Left" joint="shoulderRoll_Left" />
    <jointvel name="vel_shoulderYaw_Left" joint="shoulderYaw_Left" />
    <jointvel name="vel_elbow_Left" joint="elbow_Left" />
    <jointvel name="vel_wristYaw_Left" joint="wristYaw_Left" />
    <jointvel name="vel_wristPitch_Left" joint="wristPitch_Left" />
    <jointvel name="vel_wristRoll_Left" joint="wristRoll_Left" />
    <jointvel name="vel_shoulderPitch_Right" joint="shoulderPitch_Right" />
    <jointvel name="vel_shoulderRoll_Right" joint="shoulderRoll_Right" />
    <jointvel name="vel_shoulderYaw_Right" joint="shoulderYaw_Right" />
    <jointvel name="vel_elbow_Right" joint="elbow_Right" />
    <jointvel name="vel_wristYaw_Right" joint="wristYaw_Right" />
    <jointvel name="vel_wristPitch_Right" joint="wristPitch_Right" />
    <jointvel name="vel_wristRoll_Right" joint="wristRoll_Right" />
    <jointactuatorfrc name="force_waistRoll" joint="waistRoll" />
    <jointactuatorfrc name="force_waistPitch" joint="waistPitch" />
    <jointactuatorfrc name="force_waistYaw" joint="waistYaw" />
    <jointactuatorfrc name="force_neckYaw" joint="neckYaw" />
    <jointactuatorfrc name="force_neckPitch" joint="neckPitch" />
    <jointactuatorfrc name="force_shoulderPitch_Left" joint="shoulderPitch_Left" />
    <jointactuatorfrc name="force_shoulderRoll_Left" joint="shoulderRoll_Left" />
    <jointactuatorfrc name="force_shoulderYaw_Left" joint="shoulderYaw_Left" />
    <jointactuatorfrc name="force_elbow_Left" joint="elbow_Left" />
    <jointactuatorfrc name="force_wristYaw_Left" joint="wristYaw_Left" />
    <jointactuatorfrc name="force_wristPitch_Left" joint="wristPitch_Left" />
    <jointactuatorfrc name="force_wristRoll_Left" joint="wristRoll_Left" />
    <jointactuatorfrc name="force_shoulderPitch_Right" joint="shoulderPitch_Right" />
    <jointactuatorfrc name="force_shoulderRoll_Right" joint="shoulderRoll_Right" />
    <jointactuatorfrc name="force_shoulderYaw_Right" joint="shoulderYaw_Right" />
    <jointactuatorfrc name="force_elbow_Right" joint="elbow_Right" />
    <jointactuatorfrc name="force_wristYaw_Right" joint="wristYaw_Right" />
    <jointactuatorfrc name="force_wristPitch_Right" joint="wristPitch_Right" />
    <jointactuatorfrc name="force_wristRoll_Right" joint="wristRoll_Right" />
  </sensor>

  <contact>
    <exclude body1="wristYawLeft" body2="wristRollLeft"/>
    <!-- <exclude body1="wristRollLeft" body2="L_thumb_proximal"/>
    <exclude body1="wristYawRight" body2="wristRollRight"/>
    <exclude body1="wristRollRight" body2="R_thumb_proximal"/>
    <exclude body1="wristRollRight" body2="R_thumb_proximal"/> -->
  </contact>
</mujoco>
